# 异步编程

> * 事件循环 & 非阻塞I/O 都是 LIBUV（c++ 库）提供的能力，共同完成了 Node.js 的异步操作；
> * 事件循环是非阻塞 I/O 的基础；
> * 理解了 事件循环 & 非阻塞 I/O 就理解了 Node.js 的异步是怎样运行的；

# 1、♨️非阻塞I/O

## 1.1、concept

- I/O 即 Input/Output,一个系统的而输入和输出；
- 阻塞 I/O 和非阻塞 I/O 的区别就在于**系统接收输入再到输出的时间，能不能接收其他输入**；
- 理解非阻塞I/O：
  - 确定 **系统，输入，输出**，分别是什么
  - 在 I/O 过程中， 能不能进行其他I/O

## 1.2、case

- 系统 = 食堂阿姨 & 服务生
  - 食堂阿姨只能一份份地打饭 -> 阻塞 I/O
  - 服务生点完菜后还可以服务其他客人  -> 非阻塞 I/O
- 输入 = 点菜
- 输出 = 端菜

## 1.3、code

> 阻塞I/O

```js
const glob = require('glob')

var result = null;
console.time('glob');
result = glob.sync(__dirname + '/**/*')						// 获取目下的文件和文件名
console.log('got result');
console.timeEnd('glob');

// got result
// glob:30.607ms
```

> 非阻塞I/O

```js
const glob = require('glob')

var result = null;
console.time('glob');
glob(__dirname + '/**/*', function (err, res) {		// 获取目下的文件和文件名
    result = res;
    console.log('got result');
})
console.timeEnd('glob');
console.log(1 + 1);

// glob: 3.198ms
// 2
// got result
```

## 1.4、Node.js 架构图中理解非阻塞 I/O 

> 左边 Node.js 线程，通过调动右侧的其它 c++ 线程的方式，实现非阻塞 I/O；

* 左边 Node.js 线程中，APPLICATION 相当于顾客，其它的内容相当于点餐服务员；
  * 点餐的服务人员收到菜单后，交给后厨，可以继续服务其它顾客点菜；
* 右边其它 c++ 线程相当于后厨；

<img class="picture" src="https://cdn.nlark.com/yuque/0/2021/png/114317/1623206384912-assets/web-upload/b2d4078e-4755-4ec0-90ee-69250cd74980.png" alt="" style="width: 880px; height: 382px;">

# 2、callback

> ♨️非阻塞I/O的运行结果是需要回调函数来接收的，这种通过回调函数的方式就是异步编程！

## 2.1、回调函数格式规范

* **Node.js 规定第一个参数就是erro，第二个参数就是结果！如果第一个参数不为空，则说明异步调用出错了！**
  * error-first callbak
  * Node-style callback
  * 第一个参数是 error，后面的参数才是结果

## 2.2、异步流程控制问题

* 回调地狱

# 3、♨️事件循环

* ⚠️在 node 当中，宏任务队列和微任务队列都只是概念，没有说哪个具体队列名字就叫做宏任务队列，正确的认知应该是前面我们下面说的事件循环当中的6个阶段对应的6个基本的队列都属于宏队列；
* ⚠️有一个特别容易混淆的版本改变：
  - 如果是node10及其之前版本：
    - 宏队列当中的有几个宏任务，是要等到宏队列当中的所有宏任务全部执行完毕才会去执行微队列当中的微任务。
  - 如果是node11版本：
    - 一旦执行一个阶段里对应宏队列当中的一个宏任务(setTimeout,setInterval和setImmediate三者其中之一，不包括I/O)就立刻执行微任务队列，执行完微队列当中的所有微任务再回到刚才的宏队列执行下一个宏任务。这就跟浏览器端运行一致了。

1. js执行为单线程，所有代码皆在主线程调用栈完成执行，当主线程任务清空后才会去轮询取任务队列中任务；

2. 在node中事件**每一轮**循环按照**顺序**分为6个阶段，来自libuv的实现：
   1. timers【Timers Queue】：执行满足条件的setTimeout、setInterval回调。
   2. I/O callbacks【I/O Queue】：是否有已完成的I/O操作的回调函数，来自上一轮的poll残留。
   3. idle，prepare：可忽略
   4. poll：等待还没完成的I/O事件，会因timers和超时时间等结束等待。
   5. check【Check Queue】：执行setImmediate的回调。
   6. close callbacks【Close Queue】：关闭所有的closing handles，一些onclose事件。
3. process.nextTick 函数：
   1. 独立于 `Event Loop` 之外的，它有一个自己的队列；
   2. 当每个阶段完成后，如果存在`nextTick`队列，就会清空队列中的所有回调函数，并且优先于其他 `microtask` 执行。

# 4、♨️promise

## 4.1、concept

>  Promise 是一种异步编程的解决方案，解决了上述异步流程控制的回调地狱问题！

1. 当前 **事件循环** 得不到的结果，但未来的 **事件循环** 会给到你结果；
2. 是一个状态机：pending 只能流转到 resolve 或者 reject，resolve 和 reject 不能互相流转；
   * pending
   * fulfilled/resolved
   * rejected
3. .then & .catch 

- - resolved 状态的 Promise 会回调后面的第一个 .then；
  - rejected 状态的 Promise 会回调后面的第一个 .catch；
    - 任何一个 rejected 状态后面没有 .catch 的 Promise ，都会造成 Js环境的全局错误；

4. 执行 then 和 catch 会返回一个新的 Promise，该 Promise 最终状态根据 then 和 catch 的回调函数的执行结果决定：
   * 如果回调函数最终结果是 throw，则该 Promise 是 rejected 状态；
   * 如果回调函数最终结果是 return，则该 Promise 是 resolved 状态；
   * 如果回调函数最终 return 了一个新 Promise ，则该老 Promise 会和回调函数 return 的新 Promise 状态保持一致；
     * 这种 Promise 的链式调用中，可以串行的执行多个异步任务；
5. Promise.all([promise1, promise2]) 接受一个数组，数组中可以包含多个 promise ；
   * 数组中所有的 promise 状态都为 resolved 时，会回调后面的第一个 .then；
   * 数组中所有的 promise 状态都为 rejected 时，会回调后面的第一个 .catch；

## 4.2、code

1. promise 的状态转换以及通过 then / catch 获取内容

   ```js
   const promise = new Promise((resolve, reject) => {
     	// resolve(3);
       setTimeout(function () {
           reject(new Error(4))
       }, 500)
   })
   
   promise
       // .then(function (result) {
       //     console.log(result)		// <resolved> 3
       // })
       .catch(function (err) {
           return 1
       })
   
   setTimeout(() => {
       console.log(promise);					// <rejected> Error: 4
   }, 800)
   ```

2. promise 的链式调用

   ```js
   // 串行的执行多个异步任务
   interview(1)
       .then(()=> {
           return interview(2);
       })
       .then(()=> {
           return interview(3);
       })
       .then(()=> {
           console.log('smile')
       })
       .catch((err)=> {
           console.log('cry at ' + err.round)
       })
   
   function interview(round) {
       return new Promise((resolve, reject) => {
           setTimeout(()=> {
               if (Math.random() < 0.2) {
                   const error = new Error('failed');
                   error.round = round;
                   reject(error);
       
               } else {
                   resolve('success');
               }
           }, 500)
       })
   }
   ```

3. Promise.all 完成异步并行任务

   ```js
   Promise
       .all([interview('tencent'), interview('alibaba')])
       .then(() => {
           console.log('smile');
       })
       .catch((err) => {
           console.log('cry for ' + err.name)
       })
   
   
   function interview(name) {
       return new Promise((resolve, reject) => {
           setTimeout(() => {
               if (Math.random() < 0.2) {
                   const error = new Error('failed');
                   error.name = name;
                   reject(error);
   
               } else {
                   resolve('success');
               }
           }, 500)
       })
   }
   ```

# 5、♨️async/await

> * 👇代码中，“事件循环” 阻碍了 `throw new Error('fail')` 和 `catch` ；
>
> ```js
> function interview(callback) {
>     setTimeout(() => {
>         if (Math.random() < 0.3) {
>             callback('success');
>         }
>         throw new Error('fail')
> 
>     }, 1000);
> }
> 
> try {
>     interview(function (res) {
>         if (res === 'success') {
>             console.log('😊')
>         }
>     })
> } catch (error) {
>     console.log('😭', error);
> }
> ```
>
> 上面的代码中，` try catch `并不能捕获 ` throw new Error('fail')`  抛出的错误！,而是抛出到了JS全局！
>
> 为什么没 `try catch`  无法捕获 setTimeout 里面的 `throw` 呢？ 这就跟**调用栈** 和 **事件循环**有关系了!
>
> **每一个事件循环都是一个全新的调用栈!**  **`setTimeout`** **与  interview 是两个不同的事件循环！** 所以 catch 无法捕捉错误；
>
> * 本节 async/await 是穿越 “事件循环” 的 function ；

## 5.1、async function 是 Promise 的语法糖

1. fulfilled 状态

```js
const a = async function () {
    return 1;
}

const b = function () {
    return new Promise((resolve, reject) => {
        resolve(1)
    })
}

console.log(a());			// Promise {<fulfilled>: 1}
console.log(b());			// Promise {<fulfilled>: 1}
```

2. rejected 状态

```js
const aa = async function () {
    throw new Error('1');
}

const bb = function () {
    return new Promise((resolve, reject) => {
        reject(new Error('1'))
    })
}

console.log(aa());		// Promise {<rejected>: Error: 1
console.log(bb());		// Promise {<rejected>: Error: 1
```

## 5.2、异步编程的终极解决方案：以同步的方式写异步

1. await 关键字可以"暂停⏸"  async function 的执行；

   * await 将 resolve 括号中的结果付值给 content，接下来的代码可以获得 content 的值；

   * 达到了可以同步获取 Promise 执行结果的效果；

   ```js
   (function () {
       const result = async function () {
         	// await 会等待 后面 Promise 状态变更，并将获得的结果付值给 content ， content 获得结果后，才会执行下一行代码；
           const content = await new Promise((resolve, reject) => {
               setTimeout(() => {
                   resolve('!!!!!!')
               }, 5000);
           })
   
           console.log('content', content);
           return 4;
       }()
   
       setTimeout(() => {
           console.log('result', result);
       }, 8000);
   })()
   
   // 5s 后
   // content !!!!!!
   
   // 8s 后
   // result Promise {<fulfilled>: 4}
   ```

2. try catch 可以捕获 await 的错误；

   * await 后的 Promise 若是 rejected ，被 catch 捕捉后，不会将 reject 括号中的值付给 content ；

   ```js
   (function () {
       const result = async function () {
           let content = null;
           try {
               content = await new Promise((resolve, reject) => {
                   setTimeout(() => {
                       reject(new Error('fail'))
                   }, 500);
               })
           } catch (error) {
               console.log('error', error);
           }
   
   
           console.log('content', content);
           return 4;
       }()
   
       setTimeout(() => {
           console.log('result', result);
       }, 800);
   })()
   
   // error Error: fail
   // content null
   // result Promise {<fulfilled>: 4}
   ```

## 5.3、code

1. promise 的链式调用，使用 await 精简代码改造

   ```js
   (async function() {
       try {
           await interview(1);
           await interview(2);
           await interview(3);
       } catch (err) {
           return console.log("第 " + err.round + " 轮面试失败！");
       }
   
       console.log("通过所有面试！")
   })()
   
   
   function interview(round) {
       return new Promise((resolve, reject) => {
           setTimeout(()=> {
               if (Math.random() < 0.2) {
                   const error = new Error('failed');
                   error.round = round;
                   reject(error);
       
               } else {
                   resolve('success');
               }
           }, 500)
       })
   }
   ```

2. Promise.all 完成异步并行任务，使用 await 精简代码改造

   ```js
   (async function() {
       try {
           await Promise.all(
               [interview('tencent'), interview('huawei'), interview('alibaba')]
           )
       } catch (err) {
           return console.log(err.name + " 面试失败！")
       }
   
       console.log("所有面试全部通过！")
   })()
   
   function interview(name) {
       return new Promise((resolve, reject) => {
           setTimeout(() => {
               if (Math.random() < 0.2) {
                   const error = new Error('failed');
                   error.name = name;
                   reject(error);
   
               } else {
                   resolve('success');
               }
           }, 500)
       })
   }
   ```

   

